#VRML_SIM R2021a utf8
WorldInfo {
  basicTimeStep 8
  coordinateSystem "NUE"
}
Viewpoint {
  orientation -0.2761050782810569 -0.9216460477556371 -0.27264362894413197 1.4667091191513715
  position -47.721161481858694 5.413202358381306 14.013017981736501
}
TexturedBackground {
}
TexturedBackgroundLight {
}
CurvedRoadSegment {
  name "road(1)"
}
StraightRoadSegment {
  translation -19.942 -9.43412e-14 9.98329
  rotation 0 1 0 1.5708
  startLine [
    ""
  ]
  locked FALSE
}
StraightRoadSegment {
  translation -29.908 -9.16767e-14 9.98033
  rotation 0 1 0 1.5708
  name "road(4)"
  startLine [
    ""
  ]
  locked FALSE
}
SignPole {
  translation -20.2942 5.77316e-15 3.66119
  rotation 0 1 0 1.5708
  height 3.5
  signBoards [
    DirectionPanel {
      translation 0 1.01 0
      width 3
      height 1
      thickness 0.05
      textSize 0.45
      text "Demo 1 trial"
    }
  ]
}
StraightRoadSegment {
  translation -10.0297 -9.25649e-14 -10.0074
  rotation 0 1 0 1.5708
  name "road(3)"
  startLine [
    ""
  ]
  locked FALSE
}
StraightRoadSegment {
  translation -20.024 0.3 -9.87713
  rotation 0 1 0 1.5708
  name "road(6)"
  startLine [
    ""
  ]
  locked FALSE
}
StraightRoadSegment {
  translation -39.8934 -1.33421e-13 9.98126
  rotation 0 1 0 1.5708
  name "road(5)"
  startLine [
    ""
  ]
  locked FALSE
}
StraightRoadSegment {
  translation -9.98789 -9.07885e-14 9.98305
  rotation 0 1 0 1.5708
  name "road(7)"
  startLine [
    ""
  ]
  locked FALSE
}
CurvedRoadSegment {
  translation -0.0303781 0 -0.0121979
  rotation 0 1 0 1.5708
  name "road(2)"
  locked FALSE
}
CrashBarrier {
  translation -9.52909 1.77636e-14 13.8485
}
RectangleArena {
  translation -19.7582 -7.13318e-15 3.13343
  floorSize 40 5
}
ControlledStreetLight {
  translation -1.08968 -0.2999999999990195 14.9578
}
RectangleArena {
  translation -19.8463 -4.04399e-14 16.7743
  name "rectangle arena(1)"
  floorSize 40 5
  floorTileSize 80 10
}
BeerBottle {
  translation -27.6294 0.0004803799999762437 15.2225
  rotation 1.4772521644606383e-11 1 -6.101841851123674e-13 4.092918848457634e-06
}
SimpleTree {
  translation -25.579 -8.88179e-16 18.8737
  enableBoundingObject FALSE
  locked FALSE
}
SimpleTree {
  translation -31.4867 2.04281e-14 18.8238
  name "tree(3)"
  enableBoundingObject FALSE
  locked FALSE
}
SimpleTree {
  translation -19.2567 3.4639e-14 18.7767
  name "tree(1)"
  enableBoundingObject FALSE
  locked FALSE
}
SimpleTree {
  translation -12.1232 8.88178e-16 18.8749
  name "tree(2)"
  enableBoundingObject FALSE
  locked FALSE
}
SimpleTree {
  translation -37.6742 8.88178e-16 18.8938
  name "tree(4)"
  enableBoundingObject FALSE
  locked FALSE
}
Pedestrian {
  translation -15.4831 1.27 15.3394
  rotation 0 1 0 -1.5707953071795862
  name "pedestrian(1)"
  shirtColor 1 0 0.498039
}
Pedestrian {
  translation -27.9735 1.27 16.5255
  rotation 0 1 0 -1.5707953071795862
  name "pedestrian(2)"
}
DEF ACKERMAN Robot {
  translation -37.74169758140589 0.11785446156995485 14.836816790064224
  rotation 0.0011213484373622856 0.9999993712827293 -3.4392134012049115e-06 3.0793236018059837
  children [
    Kinect {
      hidden position_0_0 5.730168322084373e-13
      hidden translation_1 0 0.05 0
      translation 0 0.3 0
      rotation 0 1 0 1.5708
      width 820
      height 640
    }
    DEF BODY Transform {
      translation 0 0.04 0
      children [
        DEF BODY_SHAPE Shape {
          appearance PBRAppearance {
            baseColor 0.8 0.8 0.8
            roughness 1
            metalness 0
          }
          geometry Box {
            size 0.65 0.2 0.5
          }
        }
      ]
    }
    DEF FRONT_AXEL Transform {
      translation -0.23 0 0
      rotation 1 0 0 1.5707996938995747
      children [
        Shape {
          appearance PBRAppearance {
          }
          geometry Cylinder {
            height 0.7
            radius 0.01
          }
        }
      ]
    }
    DEF REAR_AXEL Transform {
      translation 0.23 0 0
      rotation 1 0 0 1.5707996938995747
      children [
        Shape {
          appearance PBRAppearance {
          }
          geometry Cylinder {
            height 0.7
            radius 0.01
          }
        }
      ]
    }
    LED {
      translation -0.33 0 -0.18
      children [
        Group {
          children [
            Shape {
              appearance PBRAppearance {
                baseColor 0.74902 0.74902 0.74902
                roughness 1
                metalness 0
              }
              geometry Box {
                size 0.04 0.07 0.1
              }
            }
            SpotLight {
              attenuation 0 0 1
              beamWidth 0.7
              color 0 0 0
              direction -1 0 0
              on FALSE
            }
          ]
        }
      ]
      name "front_right_led"
      color [
        1 1 1
      ]
    }
    LED {
      translation -0.33 0 0.18
      children [
        Group {
          children [
            Shape {
              appearance PBRAppearance {
                baseColor 0.74902 0.74902 0.74902
                roughness 1
                metalness 0
              }
              geometry Box {
                size 0.04 0.07 0.1
              }
            }
            SpotLight {
              attenuation 0 0 1
              beamWidth 0.7
              color 0 0 0
              direction -1 0 0
              on FALSE
            }
          ]
        }
      ]
      name "front_left_led"
      color [
        1 1 1
      ]
    }
    LED {
      translation 0.33 0 -0.18
      children [
        Group {
          children [
            Shape {
              appearance PBRAppearance {
                baseColor 0.74902 0.74902 0.74902
                roughness 1
                metalness 0
              }
              geometry Box {
                size 0.04 0.07 0.1
              }
            }
            SpotLight {
              attenuation 0 0 1
              beamWidth 0.7
              color 0 0 0
              direction 0 0 0
              on FALSE
            }
          ]
        }
      ]
      name "rear_right_led"
    }
    LED {
      translation 0.33 0 0.18
      children [
        Group {
          children [
            Shape {
              appearance PBRAppearance {
                baseColor 0.74902 0.74902 0.74902
                roughness 1
                metalness 0
              }
              geometry Box {
                size 0.04 0.07 0.1
              }
            }
            SpotLight {
              attenuation 0 0 1
              beamWidth 0.7
              color 0 0 0
              direction 0 0 0
              on FALSE
            }
          ]
        }
      ]
      name "rear_left_led"
    }
    DEF REAR_RIGHT_WHEEL HingeJoint {
      jointParameters HingeJointParameters {
        position 96.94742583934799
        axis 0 0 1
        anchor 0.23 0 -0.36
      }
      device [
        RotationalMotor {
          name "rear_right_wheel"
        }
      ]
      endPoint Solid {
        translation 0.22984260487486086 -0.0003645160827315922 -0.3600673054363277
        rotation 0.00011880777736633808 -0.0001358557067926173 0.9999999837139694 2.6989273582583744
        children [
          DEF WHEEL_ROT Transform {
            rotation 1 0 0 1.5708
            children [
              Shape {
                appearance PBRAppearance {
                  baseColor 0.8 0.8 0.8
                  roughness 1
                  metalness 0
                }
                geometry DEF WHEEL_CYL Cylinder {
                  height 0.06
                  radius 0.12
                }
              }
            ]
          }
        ]
        name "rear right wheel"
        boundingObject DEF WHEEL_ROT Transform {
          rotation 1 0 0 1.5708
          children [
            Shape {
              appearance PBRAppearance {
                baseColor 0.8 0.8 0.8
                roughness 1
                metalness 0
              }
              geometry DEF WHEEL_CYL Cylinder {
                height 0.06
                radius 0.12
              }
            }
          ]
        }
        physics Physics {
        }
      }
    }
    DEF REAR_LEFT_WHEEL HingeJoint {
      jointParameters HingeJointParameters {
        position 96.94719502200483
        axis 0 0 1
        anchor 0.23 0 0.36
      }
      device [
        RotationalMotor {
          name "rear_left_wheel"
        }
      ]
      endPoint Solid {
        translation 0.2298217035015791 -0.0002437570521157265 0.35995755783975447
        rotation 3.4013817559782156e-05 -7.336028649990948e-05 -0.9999999967306642 3.5838412036292833
        children [
          DEF WHEEL_ROT Transform {
            rotation 1 0 0 1.5708
            children [
              Shape {
                appearance PBRAppearance {
                  baseColor 0.8 0.8 0.8
                  roughness 1
                  metalness 0
                }
                geometry DEF WHEEL_CYL Cylinder {
                  height 0.06
                  radius 0.12
                }
              }
            ]
          }
        ]
        name "rear left wheel"
        boundingObject USE WHEEL_ROT
        physics Physics {
        }
      }
    }
    DEF RIGHT_STEER HingeJoint {
      jointParameters HingeJointParameters {
        position -3.118370771364885e-06
        axis 0 1 0
        anchor -0.23 0 -0.36
      }
      device [
        RotationalMotor {
          name "right_steer"
          minPosition -0.7
          maxPosition 0.7
        }
      ]
      endPoint Solid {
        translation -0.2300328220672142 0.0006657302359792949 -0.35991225938932137
        rotation -0.924965265016482 -0.23541363951040145 -0.2983616544488517 1.3244072935800339e-05
        children [
          DEF FRONT_RIGHT_WHEEL HingeJoint {
            jointParameters HingeJointParameters {
              position 96.94536552914724
              axis 0 0 1
            }
            device [
              RotationalMotor {
                name "front_right_wheel"
              }
            ]
            endPoint Solid {
              rotation 0 0 -1 3.585599385726145
              children [
                USE WHEEL_ROT
              ]
              boundingObject USE WHEEL_ROT
              physics Physics {
              }
            }
          }
        ]
        name "right steer"
        boundingObject DEF DUMMY Sphere {
          radius 0.01
        }
        physics Physics {
        }
      }
    }
    DEF LEFT_STEER HingeJoint {
      jointParameters HingeJointParameters {
        position 5.072770954520988e-07
        axis 0 1 0
        anchor -0.23 0 0.36
      }
      device [
        RotationalMotor {
          name "left_steer"
          minPosition -0.7
          maxPosition 0.7
        }
      ]
      endPoint Solid {
        translation -0.23004631800374967 0.0006526494331016423 0.359995179998322
        rotation 0.2383825253111904 0.11915902803210843 -0.9638334387562526 4.129100742845791e-06
        children [
          DEF FRONT_LEFT_WHEEL HingeJoint {
            jointParameters HingeJointParameters {
              position 96.94561175073595
              axis 0 0 1
            }
            device [
              RotationalMotor {
                name "front_left_wheel"
              }
            ]
            endPoint Solid {
              rotation 0 0 -1 3.5853531641374343
              children [
                USE WHEEL_ROT
              ]
              boundingObject USE WHEEL_ROT
              physics Physics {
              }
            }
          }
        ]
        name "left steer"
        boundingObject DEF DUMMY Sphere {
          radius 0.01
        }
        physics Physics {
        }
      }
    }
  ]
  name "ackerman"
  boundingObject USE BODY
  physics Physics {
  }
  controller "robot_controller"
}
Ramp30deg {
  translation -28.3194 -7.10543e-15 3.48851
}
Pedestrian {
  translation -36.7523 1.27 15.5925
  rotation 0 1 0 -1.5707953071795862
  name "pedestrian_1"
  shirtColor 1 1 0
}
