#VRML_SIM R2021a utf8
WorldInfo {
  basicTimeStep 8
  coordinateSystem "NUE"
}
Viewpoint {
  orientation -0.038444553425510494 -0.9960888674446498 -0.07955491477431337 1.5190109608133888
  position -37.89379159607551 0.6001051296104439 12.849707943680926
}
TexturedBackground {
}
TexturedBackgroundLight {
}
CurvedRoadSegment {
  name "road(1)"
}
StraightRoadSegment {
  translation -19.942 -9.43412e-14 9.98329
  rotation 0 1 0 1.5708
  startLine [
    ""
  ]
  locked FALSE
}
StraightRoadSegment {
  translation -29.908 -9.16767e-14 9.98033
  rotation 0 1 0 1.5708
  name "road(4)"
  startLine [
    ""
  ]
  locked FALSE
}
SignPole {
  translation -20.2942 5.77316e-15 3.66119
  rotation 0 1 0 1.5708
  height 3.5
  signBoards [
    DirectionPanel {
      translation 0 1.01 0
      width 3
      height 1
      thickness 0.05
      textSize 0.45
      text "Demo 1 trial"
    }
  ]
}
StraightRoadSegment {
  translation -10.0297 -9.25649e-14 -10.0074
  rotation 0 1 0 1.5708
  name "road(3)"
  startLine [
    ""
  ]
  locked FALSE
}
StraightRoadSegment {
  translation -20.024 0.3 -9.87713
  rotation 0 1 0 1.5708
  name "road(6)"
  startLine [
    ""
  ]
  locked FALSE
}
StraightRoadSegment {
  translation -39.8934 -1.33421e-13 9.98126
  rotation 0 1 0 1.5708
  name "road(5)"
  startLine [
    ""
  ]
  locked FALSE
}
StraightRoadSegment {
  translation -9.98789 -9.07885e-14 9.98305
  rotation 0 1 0 1.5708
  name "road(7)"
  startLine [
    ""
  ]
  locked FALSE
}
CurvedRoadSegment {
  translation -0.0303781 0 -0.0121979
  rotation 0 1 0 1.5708
  name "road(2)"
  locked FALSE
}
CrashBarrier {
  translation -9.52909 1.77636e-14 13.8485
}
RectangleArena {
  translation -19.7582 -7.13318e-15 3.13343
  floorSize 40 5
}
ControlledStreetLight {
  translation -1.08968 -0.2999999999990195 14.9578
}
RectangleArena {
  translation -19.8463 -4.04399e-14 16.7743
  name "rectangle arena(1)"
  floorSize 40 5
  floorTileSize 80 10
}
BeerBottle {
  translation -27.6294 0.0004803799999762437 15.2225
  rotation 1.4090119930174956e-11 1 9.151131361593887e-13 4.09291884846052e-06
}
SimpleTree {
  translation -25.579 -8.88179e-16 18.8737
  enableBoundingObject FALSE
  locked FALSE
}
SimpleTree {
  translation -31.4867 2.04281e-14 18.8238
  name "tree(3)"
  enableBoundingObject FALSE
  locked FALSE
}
SimpleTree {
  translation -19.2567 3.4639e-14 18.7767
  name "tree(1)"
  enableBoundingObject FALSE
  locked FALSE
}
SimpleTree {
  translation -12.1232 8.88178e-16 18.8749
  name "tree(2)"
  enableBoundingObject FALSE
  locked FALSE
}
SimpleTree {
  translation -37.6742 8.88178e-16 18.8938
  name "tree(4)"
  enableBoundingObject FALSE
  locked FALSE
}
Pedestrian {
  translation -15.4831 1.27 15.3394
  rotation 0 1 0 -1.5707953071795862
  name "pedestrian(1)"
  shirtColor 1 0 0.498039
}
Pedestrian {
  translation -27.9735 1.27 16.5255
  rotation 0 1 0 -1.5707953071795862
  name "pedestrian(2)"
}
DEF ACKERMAN Robot {
  translation -35.045404139319615 0.11754207808633535 12.716405373052122
  rotation 0.00045881718934686727 0.999999893423581 5.137716943485281e-05 3.1415899235198337
  children [
    VelodyneVLP-16 {
      translation 0 0.19 0
    }
    DEF BODY Transform {
      translation 0 0.04 0
      children [
        DEF BODY_SHAPE Shape {
          appearance PBRAppearance {
            baseColor 0.8 0.8 0.8
            roughness 1
            metalness 0
          }
          geometry Box {
            size 0.65 0.2 0.5
          }
        }
      ]
    }
    DEF FRONT_AXEL Transform {
      translation -0.23 0 0
      rotation 1 0 0 1.5707996938995747
      children [
        Shape {
          appearance PBRAppearance {
          }
          geometry Cylinder {
            height 0.7
            radius 0.01
          }
        }
      ]
    }
    DEF REAR_AXEL Transform {
      translation 0.23 0 0
      rotation 1 0 0 1.5707996938995747
      children [
        Shape {
          appearance PBRAppearance {
          }
          geometry Cylinder {
            height 0.7
            radius 0.01
          }
        }
      ]
    }
    LED {
      translation -0.33 0 -0.18
      children [
        Group {
          children [
            Shape {
              appearance PBRAppearance {
                baseColor 0.74902 0.74902 0.74902
                roughness 1
                metalness 0
              }
              geometry Box {
                size 0.04 0.07 0.1
              }
            }
            SpotLight {
              attenuation 0 0 1
              beamWidth 0.7
              color 0 0 0
              direction -1 0 0
              on FALSE
            }
          ]
        }
      ]
      name "front_right_led"
      color [
        1 1 1
      ]
    }
    LED {
      translation -0.33 0 0.18
      children [
        Group {
          children [
            Shape {
              appearance PBRAppearance {
                baseColor 0.74902 0.74902 0.74902
                roughness 1
                metalness 0
              }
              geometry Box {
                size 0.04 0.07 0.1
              }
            }
            SpotLight {
              attenuation 0 0 1
              beamWidth 0.7
              color 0 0 0
              direction -1 0 0
              on FALSE
            }
          ]
        }
      ]
      name "front_left_led"
      color [
        1 1 1
      ]
    }
    LED {
      translation 0.33 0 -0.18
      children [
        Group {
          children [
            Shape {
              appearance PBRAppearance {
                baseColor 0.74902 0.74902 0.74902
                roughness 1
                metalness 0
              }
              geometry Box {
                size 0.04 0.07 0.1
              }
            }
            SpotLight {
              attenuation 0 0 1
              beamWidth 0.7
              color 0 0 0
              direction 0 0 0
              on FALSE
            }
          ]
        }
      ]
      name "rear_right_led"
    }
    LED {
      translation 0.33 0 0.18
      children [
        Group {
          children [
            Shape {
              appearance PBRAppearance {
                baseColor 0.74902 0.74902 0.74902
                roughness 1
                metalness 0
              }
              geometry Box {
                size 0.04 0.07 0.1
              }
            }
            SpotLight {
              attenuation 0 0 1
              beamWidth 0.7
              color 0 0 0
              direction 0 0 0
              on FALSE
            }
          ]
        }
      ]
      name "rear_left_led"
    }
    DEF REAR_RIGHT_WHEEL HingeJoint {
      jointParameters HingeJointParameters {
        position 188.846203639029
        axis 0 0 1
        anchor 0.23 0 -0.36
      }
      device [
        RotationalMotor {
          name "rear_right_wheel"
        }
      ]
      endPoint Solid {
        translation 0.22985089274022388 0.000367984001105453 -0.3600673054363277
        rotation 0.0004453787780968265 0.000908176931002591 -0.9999994884260723 5.933259588527724
        children [
          DEF WHEEL_ROT Transform {
            rotation 1 0 0 1.5708
            children [
              Shape {
                appearance PBRAppearance {
                  baseColor 0.8 0.8 0.8
                  roughness 1
                  metalness 0
                }
                geometry DEF WHEEL_CYL Cylinder {
                  height 0.06
                  radius 0.12
                }
              }
            ]
          }
        ]
        name "rear right wheel"
        boundingObject DEF WHEEL_ROT Transform {
          rotation 1 0 0 1.5708
          children [
            Shape {
              appearance PBRAppearance {
                baseColor 0.8 0.8 0.8
                roughness 1
                metalness 0
              }
              geometry DEF WHEEL_CYL Cylinder {
                height 0.06
                radius 0.12
              }
            }
          ]
        }
        physics Physics {
        }
        linearVelocity -3.301453463038825e-08 -3.5168014628454054e-11 -1.2531445528607244e-09
        angularVelocity 1.8079047506261566e-10 6.283072191554331e-09 2.393181740696029e-07
      }
    }
    DEF REAR_LEFT_WHEEL HingeJoint {
      jointParameters HingeJointParameters {
        position 189.36723704512855
        axis 0 0 1
        anchor 0.23 0 0.36
      }
      device [
        RotationalMotor {
          name "rear_left_wheel"
        }
      ]
      endPoint Solid {
        translation 0.2298095543685573 0.00023438771996351818 0.35995755783975447
        rotation 8.625481811546787e-05 0.00016579412089814477 0.9999999825362077 0.8716065309471885
        children [
          DEF WHEEL_ROT Transform {
            rotation 1 0 0 1.5708
            children [
              Shape {
                appearance PBRAppearance {
                  baseColor 0.8 0.8 0.8
                  roughness 1
                  metalness 0
                }
                geometry DEF WHEEL_CYL Cylinder {
                  height 0.06
                  radius 0.12
                }
              }
            ]
          }
        ]
        name "rear left wheel"
        boundingObject USE WHEEL_ROT
        physics Physics {
        }
        linearVelocity -4.321284515924074e-08 -2.5750117040465602e-11 -1.87551619849106e-09
        angularVelocity 2.5530624554900375e-10 6.275259743079349e-09 3.161593875794822e-07
      }
    }
    DEF RIGHT_STEER HingeJoint {
      jointParameters HingeJointParameters {
        position 4.189912132926295e-06
        axis 0 1 0
        anchor -0.23 0 -0.36
      }
      device [
        RotationalMotor {
          name "right_steer"
          minPosition -0.7
          maxPosition 0.7
        }
      ]
      endPoint Solid {
        translation -0.2300328214259801 0.000665730235979293 -0.35991225914945074
        rotation -0.9049669230435285 0.3095561909612901 -0.29190723326883383 1.3536948384079384e-05
        children [
          DEF FRONT_RIGHT_WHEEL HingeJoint {
            jointParameters HingeJointParameters {
              position 190.6410511734533
              axis 0 0 1
            }
            device [
              RotationalMotor {
                name "front_right_wheel"
              }
            ]
            endPoint Solid {
              rotation 0 0 1 2.1454919580656977
              children [
                USE WHEEL_ROT
              ]
              boundingObject USE WHEEL_ROT
              physics Physics {
              }
              linearVelocity 6.43899941876332e-09 3.733589992545877e-11 1.6193640935685942e-09
              angularVelocity -4.785876881504539e-10 3.951616250558973e-08 -1.1130376297902883e-09
            }
          }
        ]
        name "right steer"
        boundingObject DEF DUMMY Sphere {
          radius 0.01
        }
        physics Physics {
        }
        linearVelocity -7.519952933194052e-09 3.875357277931597e-11 -4.239848984505559e-10
        angularVelocity -2.818342123034666e-10 3.964809340244828e-08 1.9128339532481326e-09
      }
    }
    DEF LEFT_STEER HingeJoint {
      jointParameters HingeJointParameters {
        position -1.1167521107690856e-06
        axis 0 1 0
        anchor -0.23 0 0.36
      }
      device [
        RotationalMotor {
          name "left_steer"
          minPosition -0.7
          maxPosition 0.7
        }
      ]
      endPoint Solid {
        translation -0.2300463179959218 0.0006526494331016367 0.3599951799231002
        rotation 0.2314363446129187 -0.266116675342475 -0.9357452289468957 4.253700831762593e-06
        children [
          DEF FRONT_LEFT_WHEEL HingeJoint {
            jointParameters HingeJointParameters {
              position 188.85539399743143
              axis 0 0 1
            }
            device [
              RotationalMotor {
                name "front_left_wheel"
              }
            ]
            endPoint Solid {
              rotation 0 0 1 0.35983478204384034
              children [
                USE WHEEL_ROT
              ]
              boundingObject USE WHEEL_ROT
              physics Physics {
              }
              linearVelocity 3.210202340979948e-09 2.3598962086549914e-11 1.4405954975584412e-09
              angularVelocity -5.254401944339517e-10 -3.4394771615760826e-08 4.1814534434703453e-10
            }
          }
        ]
        name "left steer"
        boundingObject DEF DUMMY Sphere {
          radius 0.01
        }
        physics Physics {
        }
        linearVelocity -1.1403439549537629e-08 2.464039311938435e-11 -5.118813494999067e-10
        angularVelocity -2.4836695033728367e-10 -3.455976478166196e-08 1.983323558153868e-09
      }
    }
  ]
  name "ackerman"
  boundingObject USE BODY
  physics Physics {
  }
  controller "robot_controller"
}
Ramp30deg {
  translation -28.3194 -7.10543e-15 3.48851
}
Pedestrian {
  translation -36.7523 1.27 15.5925
  rotation 0 1 0 -1.5707953071795862
  name "pedestrian_1"
  shirtColor 1 1 0
}
