#VRML_SIM R2021a utf8
WorldInfo {
  basicTimeStep 8
  coordinateSystem "NUE"
}
Viewpoint {
  orientation -0.004272292126131237 -0.9779389110713761 -0.2088473934060949 3.101587524374205
  position -1.8791177248452264 6.272136845086588 -14.43062102172112
}
TexturedBackground {
}
TexturedBackgroundLight {
  castShadows FALSE
}
RectangleArena {
  rotation 0 1 0 1.0150305250839343e-06
  floorSize 5 5
  floorAppearance Parquetry {
    type "dark strip"
    colorOverride 0 0 0
  }
  wallHeight 1
}
CardboardBox {
  translation -1.34 0.3 1.32808e-05
  rotation 0 1 0 4.692820414042842e-06
}
DEF ACKERMAN Robot {
  translation 4.683919829686495e-10 0.1194108397458982 -4.687611694751022e-11
  rotation 8.761495152449117e-06 0.9999999961160843 8.769873156946516e-05 0.01203170501273612
  children [
    Gyro {
    }
    Accelerometer {
    }
    InertialUnit {
      name "imu"
    }
    GPS {
    }
    RobotisLds01 {
      translation 0 0.16 0
      rotation 0 1 0 1.57079
      name "RobotisLds01"
    }
    DEF BODY Transform {
      translation 0 0.04 0
      children [
        DEF BODY_SHAPE Shape {
          appearance PBRAppearance {
            baseColor 0.8 0.8 0.8
            roughness 1
            metalness 0
          }
          geometry Box {
            size 0.65 0.2 0.5
          }
        }
      ]
    }
    DEF FRONT_AXEL Transform {
      translation -0.23 0 0
      rotation 1 0 0 1.5707996938995747
      children [
        Shape {
          appearance PBRAppearance {
          }
          geometry Cylinder {
            height 0.6
            radius 0.01
          }
        }
      ]
    }
    DEF REAR_AXEL Transform {
      translation 0.23 0 0
      rotation 1 0 0 1.5707996938995747
      children [
        Shape {
          appearance PBRAppearance {
          }
          geometry Cylinder {
            height 0.6
            radius 0.01
          }
        }
      ]
    }
    LED {
      translation -0.33 0 -0.18
      children [
        Group {
          children [
            Shape {
              appearance PBRAppearance {
                baseColor 0.74902 0.74902 0.74902
                roughness 1
                metalness 0
              }
              geometry Box {
                size 0.04 0.07 0.1
              }
            }
            SpotLight {
              attenuation 0 0 1
              beamWidth 0.7
              color 0 0 0
              direction -1 0 0
              on FALSE
            }
          ]
        }
      ]
      name "front_right_led"
      color [
        1 1 1
      ]
    }
    LED {
      translation -0.33 0 0.18
      children [
        Group {
          children [
            Shape {
              appearance PBRAppearance {
                baseColor 0.74902 0.74902 0.74902
                roughness 1
                metalness 0
              }
              geometry Box {
                size 0.04 0.07 0.1
              }
            }
            SpotLight {
              attenuation 0 0 1
              beamWidth 0.7
              color 0 0 0
              direction -1 0 0
              on FALSE
            }
          ]
        }
      ]
      name "front_left_led"
      color [
        1 1 1
      ]
    }
    LED {
      translation 0.33 0 -0.18
      children [
        Group {
          children [
            Shape {
              appearance PBRAppearance {
                baseColor 0.74902 0.74902 0.74902
                roughness 1
                metalness 0
              }
              geometry Box {
                size 0.04 0.07 0.1
              }
            }
            SpotLight {
              attenuation 0 0 1
              beamWidth 0.7
              color 0 0 0
              direction 0 0 0
              on FALSE
            }
          ]
        }
      ]
      name "rear_right_led"
    }
    LED {
      translation 0.33 0 0.18
      children [
        Group {
          children [
            Shape {
              appearance PBRAppearance {
                baseColor 0.74902 0.74902 0.74902
                roughness 1
                metalness 0
              }
              geometry Box {
                size 0.04 0.07 0.1
              }
            }
            SpotLight {
              attenuation 0 0 1
              beamWidth 0.7
              color 0 0 0
              direction 0 0 0
              on FALSE
            }
          ]
        }
      ]
      name "rear_left_led"
    }
    DEF REAR_RIGHT_WHEEL HingeJoint {
      jointParameters HingeJointParameters {
        position -53.346766232202874
        axis 0 0 1
        anchor 0.23 0 -0.3
      }
      device [
        RotationalMotor {
          name "rear_right_wheel"
        }
      ]
      endPoint DEF REAR_RIGHT_SOLID Solid {
        translation 0.23 0 -0.3
        rotation 0 0 -1 3.0812837747661828
        children [
          DEF WHEEL_ROT Transform {
            rotation 1 0 0 1.5708
            children [
              Shape {
                appearance PBRAppearance {
                  baseColor 0.8 0.8 0.8
                  roughness 1
                  metalness 0
                }
                geometry DEF WHEEL_CYL Cylinder {
                  height 0.06
                  radius 0.12
                }
              }
            ]
          }
        ]
        name "rear right wheel"
        boundingObject DEF WHEEL_ROT Transform {
          rotation 1 0 0 1.5708
          children [
            Shape {
              appearance PBRAppearance {
                baseColor 0.8 0.8 0.8
                roughness 1
                metalness 0
              }
              geometry DEF WHEEL_CYL Cylinder {
                height 0.06
                radius 0.12
              }
            }
          ]
        }
        physics Physics {
        }
      }
    }
    DEF REAR_LEFT_WHEEL HingeJoint {
      jointParameters HingeJointParameters {
        position 29.0358526956649
        axis 0 0 1
        anchor 0.23 0 0.3
      }
      device [
        RotationalMotor {
          name "rear_left_wheel"
        }
      ]
      endPoint DEF REAR_LEFT_SOLID Solid {
        translation 0.23 0 0.3
        rotation 0 0 0.9999999999999999 3.9031114669465543
        children [
          DEF WHEEL_ROT Transform {
            rotation 1 0 0 1.5708
            children [
              Shape {
                appearance PBRAppearance {
                  baseColor 0.8 0.8 0.8
                  roughness 1
                  metalness 0
                }
                geometry DEF WHEEL_CYL Cylinder {
                  height 0.06
                  radius 0.12
                }
              }
            ]
          }
        ]
        name "rear left wheel"
        boundingObject USE WHEEL_ROT
        physics Physics {
        }
      }
    }
    DEF FRONT_RIGHT_WHEEL HingeJoint {
      jointParameters HingeJointParameters {
        position -45.9969707429769
        axis 0 0 1
        anchor -0.23 0 -0.3
      }
      device [
        RotationalMotor {
          name "front_right_wheel"
        }
      ]
      endPoint DEF FRONT_RIGHT_SOLID Solid {
        translation -0.23 0 -0.3
        rotation 0 0 0.9999999999999999 4.268511714459793
        children [
          USE WHEEL_ROT
        ]
        boundingObject USE WHEEL_ROT
        physics Physics {
        }
      }
    }
    DEF FRONT_LEFT_WHEEL HingeJoint {
      jointParameters HingeJointParameters {
        position 36.96447591525427
        axis 0 0 1
        anchor -0.23 0 0.3
      }
      device [
        RotationalMotor {
          name "front_left_wheel"
        }
      ]
      endPoint DEF FRONT_LEFT_SOLID Solid {
        translation -0.23 0 0.3
        rotation 0 0 -1 0.7346359278232498
        children [
          USE WHEEL_ROT
        ]
        name "solid(1)"
        boundingObject USE WHEEL_ROT
        physics Physics {
        }
      }
    }
  ]
  name "ackerman"
  boundingObject USE BODY
  physics Physics {
    density -1
    mass 1
  }
  controller "<extern>"
  supervisor TRUE
  linearVelocity -1.1957031848453124e-15 -3.6061907691588253e-13 6.01277031920989e-17
  angularVelocity 2.350616684070533e-16 -5.964289717099926e-15 4.425958430298623e-15
}
