#VRML_SIM R2021a utf8
WorldInfo {
  basicTimeStep 8
  coordinateSystem "NUE"
}
Viewpoint {
  orientation 0.9399497417314604 0.27559468876615373 0.20135056628390105 5.222341024819357
  position 0.04488005070254174 1.844025991727198 1.031463211386312
}
TexturedBackground {
}
TexturedBackgroundLight {
}
RectangleArena {
  floorSize 5 5
}
CardboardBox {
  translation 0.58 0.3 -1.06
}
DEF ACKERMAN Robot {
  translation -1.7976168700034643e-08 0.11620885574581999 -7.636792833134356e-08
  rotation -0.9733948845886086 6.577308640946133e-09 0.22913401898611543 6.537666074389555e-07
  children [
    Accelerometer {
    }
    InertialUnit {
      name "imu"
    }
    GPS {
    }
    RobotisLds01 {
      translation 0 0.16 0
      name "RobotisLds01"
    }
    DEF BODY Transform {
      translation 0 0.04 0
      children [
        DEF BODY_SHAPE Shape {
          appearance PBRAppearance {
            baseColor 0.8 0.8 0.8
            roughness 1
            metalness 0
          }
          geometry Box {
            size 0.65 0.2 0.5
          }
        }
      ]
    }
    DEF FRONT_AXEL Transform {
      translation -0.23 0 0
      rotation 1 0 0 1.5707996938995747
      children [
        Shape {
          appearance PBRAppearance {
          }
          geometry Cylinder {
            height 0.6
            radius 0.01
          }
        }
      ]
    }
    DEF REAR_AXEL Transform {
      translation 0.23 0 0
      rotation 1 0 0 1.5707996938995747
      children [
        Shape {
          appearance PBRAppearance {
          }
          geometry Cylinder {
            height 0.6
            radius 0.01
          }
        }
      ]
    }
    LED {
      translation -0.33 0 -0.18
      children [
        Group {
          children [
            Shape {
              appearance PBRAppearance {
                baseColor 0.74902 0.74902 0.74902
                roughness 1
                metalness 0
              }
              geometry Box {
                size 0.04 0.07 0.1
              }
            }
            SpotLight {
              attenuation 0 0 1
              beamWidth 0.7
              color 0 0 0
              direction -1 0 0
              on FALSE
            }
          ]
        }
      ]
      name "front_right_led"
      color [
        1 1 1
      ]
    }
    LED {
      translation -0.33 0 0.18
      children [
        Group {
          children [
            Shape {
              appearance PBRAppearance {
                baseColor 0.74902 0.74902 0.74902
                roughness 1
                metalness 0
              }
              geometry Box {
                size 0.04 0.07 0.1
              }
            }
            SpotLight {
              attenuation 0 0 1
              beamWidth 0.7
              color 0 0 0
              direction -1 0 0
              on FALSE
            }
          ]
        }
      ]
      name "front_left_led"
      color [
        1 1 1
      ]
    }
    LED {
      translation 0.33 0 -0.18
      children [
        Group {
          children [
            Shape {
              appearance PBRAppearance {
                baseColor 0.74902 0.74902 0.74902
                roughness 1
                metalness 0
              }
              geometry Box {
                size 0.04 0.07 0.1
              }
            }
            SpotLight {
              attenuation 0 0 1
              beamWidth 0.7
              color 0 0 0
              direction 0 0 0
              on FALSE
            }
          ]
        }
      ]
      name "rear_right_led"
    }
    LED {
      translation 0.33 0 0.18
      children [
        Group {
          children [
            Shape {
              appearance PBRAppearance {
                baseColor 0.74902 0.74902 0.74902
                roughness 1
                metalness 0
              }
              geometry Box {
                size 0.04 0.07 0.1
              }
            }
            SpotLight {
              attenuation 0 0 1
              beamWidth 0.7
              color 0 0 0
              direction 0 0 0
              on FALSE
            }
          ]
        }
      ]
      name "rear_left_led"
    }
    DEF REAR_RIGHT_WHEEL HingeJoint {
      jointParameters HingeJointParameters {
        position -0.2688217763741941
        axis 0 0 1
        anchor 0.23 0 -0.3
      }
      device [
        RotationalMotor {
          name "rear_right_wheel"
        }
      ]
      endPoint Solid {
        translation 0.23 0 -0.3
        rotation 0 0 -1 0.26882177637419385
        children [
          DEF WHEEL_ROT Transform {
            rotation 1 0 0 1.5708
            children [
              Shape {
                appearance PBRAppearance {
                  baseColor 0.8 0.8 0.8
                  roughness 1
                  metalness 0
                }
                geometry DEF WHEEL_CYL Cylinder {
                  height 0.06
                  radius 0.12
                }
              }
            ]
          }
        ]
        name "rear right wheel"
        boundingObject DEF WHEEL_ROT Transform {
          rotation 1 0 0 1.5708
          children [
            Shape {
              appearance PBRAppearance {
                baseColor 0.8 0.8 0.8
                roughness 1
                metalness 0
              }
              geometry DEF WHEEL_CYL Cylinder {
                height 0.06
                radius 0.12
              }
            }
          ]
        }
        physics Physics {
        }
        linearVelocity -2.4211628283830996e-11 -1.303115361201801e-11 -1.0061101182581225e-13
        angularVelocity -2.4665888948790608e-14 1.3673384214224085e-12 2.0481679529907916e-10
      }
    }
    DEF REAR_LEFT_WHEEL HingeJoint {
      jointParameters HingeJointParameters {
        position -0.24601636921317274
        axis 0 0 1
        anchor 0.23 0 0.3
      }
      device [
        RotationalMotor {
          name "rear_left_wheel"
        }
      ]
      endPoint Solid {
        translation 0.23 0 0.3
        rotation 0 0 -1 0.24601636921317274
        children [
          DEF WHEEL_ROT Transform {
            rotation 1 0 0 1.5708
            children [
              Shape {
                appearance PBRAppearance {
                  baseColor 0.8 0.8 0.8
                  roughness 1
                  metalness 0
                }
                geometry DEF WHEEL_CYL Cylinder {
                  height 0.06
                  radius 0.12
                }
              }
            ]
          }
        ]
        name "rear left wheel"
        boundingObject USE WHEEL_ROT
        physics Physics {
        }
        linearVelocity -2.4107724890904836e-11 -1.3031070269167146e-11 -1.0105504356077652e-13
        angularVelocity -2.4678504593322463e-14 1.3673408548992458e-12 2.067001863232092e-10
      }
    }
    DEF FRONT_RIGHT_WHEEL HingeJoint {
      jointParameters HingeJointParameters {
        position 0.00020088212448386838
        axis 0 0 1
        anchor -0.23 0 -0.3
      }
      device [
        RotationalMotor {
          name "front_right_wheel"
        }
      ]
      endPoint Solid {
        translation -0.23 0 -0.3
        rotation 0 0 1 0.00020088212471155835
        children [
          USE WHEEL_ROT
        ]
        boundingObject USE WHEEL_ROT
        physics Physics {
        }
        linearVelocity -2.5189160637140254e-11 1.3033960267272429e-11 1.0101814136653581e-13
        angularVelocity 2.5841670354368507e-14 1.3673462064533589e-12 2.167310702177252e-10
      }
    }
    DEF FRONT_LEFT_WHEEL HingeJoint {
      jointParameters HingeJointParameters {
        position 0.38755663546877833
        axis 0 0 1
        anchor -0.23 0 0.3
      }
      device [
        RotationalMotor {
          name "front_left_wheel"
        }
      ]
      endPoint Solid {
        translation -0.23 0 0.3
        rotation 0 0 1 0.3875566354687784
        children [
          USE WHEEL_ROT
        ]
        name "solid(1)"
        boundingObject USE WHEEL_ROT
        physics Physics {
        }
        linearVelocity -2.2911581557453154e-11 1.3034294859354868e-11 1.0104237973224833e-13
        angularVelocity 2.6622966515914584e-14 1.3673310864320365e-12 1.92113531328137e-10
      }
    }
  ]
  name "ackerman"
  boundingObject USE BODY
  physics Physics {
  }
  controller "<extern>"
  supervisor TRUE
  linearVelocity -2.0820729268371104e-11 -9.91458744137017e-16 -9.04185093974769e-16
  angularVelocity 7.574610269933291e-16 1.3699258024126358e-12 -5.822294476301386e-11
}
