#VRML_SIM R2021a utf8
WorldInfo {
  basicTimeStep 8
  coordinateSystem "NUE"
}
Viewpoint {
  orientation 0.9399497417314604 0.27559468876615373 0.20135056628390105 5.222341024819357
  position 0.04488005070254174 1.844025991727198 1.031463211386312
}
TexturedBackground {
}
TexturedBackgroundLight {
}
RectangleArena {
  floorSize 5 5
}
CardboardBox {
  translation 0.58 0.3 -1.06
}
DEF ACKERMAN Robot {
  translation -1.797616874196362e-08 0.11620885574581999 -7.636792844954531e-08
  rotation -0.9733948845908359 6.521557633268995e-09 0.22913401897665323 6.537666074422139e-07
  children [
    Gyro {
    }
    InertialUnit {
      name "imu"
    }
    GPS {
      name "gps"
    }
    RobotisLds01 {
      translation 0 0.16 0
      name "RobotisLds01"
    }
    DEF BODY Transform {
      translation 0 0.04 0
      children [
        DEF BODY_SHAPE Shape {
          appearance PBRAppearance {
            baseColor 0.8 0.8 0.8
            roughness 1
            metalness 0
          }
          geometry Box {
            size 0.65 0.2 0.5
          }
        }
      ]
    }
    DEF FRONT_AXEL Transform {
      translation -0.23 0 0
      rotation 1 0 0 1.5707996938995747
      children [
        Shape {
          appearance PBRAppearance {
          }
          geometry Cylinder {
            height 0.6
            radius 0.01
          }
        }
      ]
    }
    DEF REAR_AXEL Transform {
      translation 0.23 0 0
      rotation 1 0 0 1.5707996938995747
      children [
        Shape {
          appearance PBRAppearance {
          }
          geometry Cylinder {
            height 0.6
            radius 0.01
          }
        }
      ]
    }
    LED {
      translation -0.33 0 -0.18
      children [
        Group {
          children [
            Shape {
              appearance PBRAppearance {
                baseColor 0.74902 0.74902 0.74902
                roughness 1
                metalness 0
              }
              geometry Box {
                size 0.04 0.07 0.1
              }
            }
            SpotLight {
              attenuation 0 0 1
              beamWidth 0.7
              color 0 0 0
              direction -1 0 0
              on FALSE
            }
          ]
        }
      ]
      name "front_right_led"
      color [
        1 1 1
      ]
    }
    LED {
      translation -0.33 0 0.18
      children [
        Group {
          children [
            Shape {
              appearance PBRAppearance {
                baseColor 0.74902 0.74902 0.74902
                roughness 1
                metalness 0
              }
              geometry Box {
                size 0.04 0.07 0.1
              }
            }
            SpotLight {
              attenuation 0 0 1
              beamWidth 0.7
              color 0 0 0
              direction -1 0 0
              on FALSE
            }
          ]
        }
      ]
      name "front_left_led"
      color [
        1 1 1
      ]
    }
    LED {
      translation 0.33 0 -0.18
      children [
        Group {
          children [
            Shape {
              appearance PBRAppearance {
                baseColor 0.74902 0.74902 0.74902
                roughness 1
                metalness 0
              }
              geometry Box {
                size 0.04 0.07 0.1
              }
            }
            SpotLight {
              attenuation 0 0 1
              beamWidth 0.7
              color 0 0 0
              direction 0 0 0
              on FALSE
            }
          ]
        }
      ]
      name "rear_right_led"
    }
    LED {
      translation 0.33 0 0.18
      children [
        Group {
          children [
            Shape {
              appearance PBRAppearance {
                baseColor 0.74902 0.74902 0.74902
                roughness 1
                metalness 0
              }
              geometry Box {
                size 0.04 0.07 0.1
              }
            }
            SpotLight {
              attenuation 0 0 1
              beamWidth 0.7
              color 0 0 0
              direction 0 0 0
              on FALSE
            }
          ]
        }
      ]
      name "rear_left_led"
    }
    DEF REAR_RIGHT_WHEEL HingeJoint {
      jointParameters HingeJointParameters {
        position -0.2688217763741941
        axis 0 0 1
        anchor 0.23 0 -0.3
      }
      device [
        RotationalMotor {
          name "rear_right_wheel"
        }
      ]
      endPoint Solid {
        translation 0.23 0 -0.3
        rotation 0 0 -1 0.26882177637419385
        children [
          DEF WHEEL_ROT Transform {
            rotation 1 0 0 1.5708
            children [
              Shape {
                appearance PBRAppearance {
                  baseColor 0.8 0.8 0.8
                  roughness 1
                  metalness 0
                }
                geometry DEF WHEEL_CYL Cylinder {
                  height 0.06
                  radius 0.12
                }
              }
            ]
          }
        ]
        name "rear right wheel"
        boundingObject DEF WHEEL_ROT Transform {
          rotation 1 0 0 1.5708
          children [
            Shape {
              appearance PBRAppearance {
                baseColor 0.8 0.8 0.8
                roughness 1
                metalness 0
              }
              geometry DEF WHEEL_CYL Cylinder {
                height 0.06
                radius 0.12
              }
            }
          ]
        }
        physics Physics {
        }
        linearVelocity -2.421143025169518e-11 -1.30306086314031e-11 -1.0067061686412352e-13
        angularVelocity -2.4330284879811047e-14 1.3679692380590239e-12 2.0481548869206387e-10
      }
    }
    DEF REAR_LEFT_WHEEL HingeJoint {
      jointParameters HingeJointParameters {
        position -0.24601636921317277
        axis 0 0 1
        anchor 0.23 0 0.3
      }
      device [
        RotationalMotor {
          name "rear_left_wheel"
        }
      ]
      endPoint Solid {
        translation 0.23 0 0.3
        rotation 0 0 -0.9999999999999999 0.24601636921317274
        children [
          DEF WHEEL_ROT Transform {
            rotation 1 0 0 1.5708
            children [
              Shape {
                appearance PBRAppearance {
                  baseColor 0.8 0.8 0.8
                  roughness 1
                  metalness 0
                }
                geometry DEF WHEEL_CYL Cylinder {
                  height 0.06
                  radius 0.12
                }
              }
            ]
          }
        ]
        name "rear left wheel"
        boundingObject USE WHEEL_ROT
        physics Physics {
        }
        linearVelocity -2.410769953118734e-11 -1.3031195544998859e-11 -1.0120203461700895e-13
        angularVelocity -2.5349719253166998e-14 1.3679709693325595e-12 2.0669972194988454e-10
      }
    }
    DEF FRONT_RIGHT_WHEEL HingeJoint {
      jointParameters HingeJointParameters {
        position 0.00020088212448389419
        axis 0 0 1
        anchor -0.23 0 -0.3
      }
      device [
        RotationalMotor {
          name "front_right_wheel"
        }
      ]
      endPoint Solid {
        translation -0.23 0 -0.3
        rotation 0 0 1 0.00020088212471155835
        children [
          USE WHEEL_ROT
        ]
        boundingObject USE WHEEL_ROT
        physics Physics {
        }
        linearVelocity -2.5188976456866783e-11 1.3034420460013577e-11 1.0103258650224436e-13
        angularVelocity 2.5506062115689108e-14 1.3679780438999775e-12 2.1672995635745978e-10
      }
    }
    DEF FRONT_LEFT_WHEEL HingeJoint {
      jointParameters HingeJointParameters {
        position 0.38755663546877833
        axis 0 0 1
        anchor -0.23 0 0.3
      }
      device [
        RotationalMotor {
          name "front_left_wheel"
        }
      ]
      endPoint Solid {
        translation -0.23 0 0.3
        rotation 0 0 1 0.3875566354687784
        children [
          USE WHEEL_ROT
        ]
        name "solid(1)"
        boundingObject USE WHEEL_ROT
        physics Physics {
        }
        linearVelocity -2.291153300821852e-11 1.3034169019708485e-11 1.0102829419895538e-13
        angularVelocity 2.6287360443700896e-14 1.3679615414761316e-12 1.9211277476366688e-10
      }
    }
  ]
  name "ackerman"
  boundingObject USE BODY
  physics Physics {
    density -1
    mass 1
  }
  controller "<extern>"
  supervisor TRUE
  linearVelocity -2.0820921667719307e-11 -9.355342157889781e-16 -9.68198923785366e-16
  angularVelocity -1.623675065514744e-18 1.3705589456515402e-12 -5.822371572987426e-11
}
